2022-06-23 16:14:28,002 INFO    MainThread:8772 [internal.py:wandb_internal():93] W&B internal server running at pid: 8772, started at: 2022-06-23 16:14:28.002374
2022-06-23 16:14:28,003 INFO    WriterThread:8772 [datastore.py:open_for_write():75] open: /media/scau/21B1CA0D9A1CBC09/DL/yolov5_obb-master/yolov5_obb-master/wandb/run-20220623_161427-1z09apmw/run-1z09apmw.wandb
2022-06-23 16:14:28,005 DEBUG   SenderThread:8772 [sender.py:send():235] send: header
2022-06-23 16:14:28,005 DEBUG   SenderThread:8772 [sender.py:send():235] send: run
2022-06-23 16:14:28,012 INFO    SenderThread:8772 [sender.py:_maybe_setup_resume():493] checking resume status for None/YOLOv5/1z09apmw
2022-06-23 16:14:57,648 DEBUG   HandlerThread:8772 [handler.py:handle_request():141] handle_request: shutdown
2022-06-23 16:14:57,649 INFO    HandlerThread:8772 [handler.py:finish():806] shutting down handler
2022-06-23 16:14:58,010 INFO    WriterThread:8772 [datastore.py:close():279] close: /media/scau/21B1CA0D9A1CBC09/DL/yolov5_obb-master/yolov5_obb-master/wandb/run-20220623_161427-1z09apmw/run-1z09apmw.wandb
2022-06-23 16:15:01,677 ERROR   SenderThread:8772 [retry.py:__call__():126] Retry attempt failed:
Traceback (most recent call last):
  File "/home/scau/anaconda3/envs/yolov5/lib/python3.7/site-packages/urllib3/connection.py", line 175, in _new_conn
    (self._dns_host, self.port), self.timeout, **extra_kw
  File "/home/scau/anaconda3/envs/yolov5/lib/python3.7/site-packages/urllib3/util/connection.py", line 95, in create_connection
    raise err
  File "/home/scau/anaconda3/envs/yolov5/lib/python3.7/site-packages/urllib3/util/connection.py", line 85, in create_connection
    sock.connect(sa)
socket.timeout: timed out

During handling of the above exception, another exception occurred:

Traceback (most recent call last):
  File "/home/scau/anaconda3/envs/yolov5/lib/python3.7/site-packages/urllib3/connectionpool.py", line 710, in urlopen
    chunked=chunked,
  File "/home/scau/anaconda3/envs/yolov5/lib/python3.7/site-packages/urllib3/connectionpool.py", line 386, in _make_request
    self._validate_conn(conn)
  File "/home/scau/anaconda3/envs/yolov5/lib/python3.7/site-packages/urllib3/connectionpool.py", line 1040, in _validate_conn
    conn.connect()
  File "/home/scau/anaconda3/envs/yolov5/lib/python3.7/site-packages/urllib3/connection.py", line 358, in connect
    self.sock = conn = self._new_conn()
  File "/home/scau/anaconda3/envs/yolov5/lib/python3.7/site-packages/urllib3/connection.py", line 182, in _new_conn
    % (self.host, self.timeout),
urllib3.exceptions.ConnectTimeoutError: (<urllib3.connection.HTTPSConnection object at 0x7fa8944df240>, 'Connection to api.wandb.ai timed out. (connect timeout=10)')

During handling of the above exception, another exception occurred:

Traceback (most recent call last):
  File "/home/scau/anaconda3/envs/yolov5/lib/python3.7/site-packages/requests/adapters.py", line 450, in send
    timeout=timeout
  File "/home/scau/anaconda3/envs/yolov5/lib/python3.7/site-packages/urllib3/connectionpool.py", line 786, in urlopen
    method, url, error=e, _pool=self, _stacktrace=sys.exc_info()[2]
  File "/home/scau/anaconda3/envs/yolov5/lib/python3.7/site-packages/urllib3/util/retry.py", line 592, in increment
    raise MaxRetryError(_pool, url, error or ResponseError(cause))
urllib3.exceptions.MaxRetryError: HTTPSConnectionPool(host='api.wandb.ai', port=443): Max retries exceeded with url: /graphql (Caused by ConnectTimeoutError(<urllib3.connection.HTTPSConnection object at 0x7fa8944df240>, 'Connection to api.wandb.ai timed out. (connect timeout=10)'))

During handling of the above exception, another exception occurred:

Traceback (most recent call last):
  File "/home/scau/anaconda3/envs/yolov5/lib/python3.7/site-packages/wandb/sdk/lib/retry.py", line 102, in __call__
    result = self._call_fn(*args, **kwargs)
  File "/home/scau/anaconda3/envs/yolov5/lib/python3.7/site-packages/wandb/sdk/internal/internal_api.py", line 140, in execute
    return self.client.execute(*args, **kwargs)
  File "/home/scau/anaconda3/envs/yolov5/lib/python3.7/site-packages/wandb/vendor/gql-0.2.0/wandb_gql/client.py", line 52, in execute
    result = self._get_result(document, *args, **kwargs)
  File "/home/scau/anaconda3/envs/yolov5/lib/python3.7/site-packages/wandb/vendor/gql-0.2.0/wandb_gql/client.py", line 60, in _get_result
    return self.transport.execute(document, *args, **kwargs)
  File "/home/scau/anaconda3/envs/yolov5/lib/python3.7/site-packages/wandb/vendor/gql-0.2.0/wandb_gql/transport/requests.py", line 38, in execute
    request = requests.post(self.url, **post_args)
  File "/home/scau/anaconda3/envs/yolov5/lib/python3.7/site-packages/requests/api.py", line 117, in post
    return request('post', url, data=data, json=json, **kwargs)
  File "/home/scau/anaconda3/envs/yolov5/lib/python3.7/site-packages/requests/api.py", line 61, in request
    return session.request(method=method, url=url, **kwargs)
  File "/home/scau/anaconda3/envs/yolov5/lib/python3.7/site-packages/requests/sessions.py", line 529, in request
    resp = self.send(prep, **send_kwargs)
  File "/home/scau/anaconda3/envs/yolov5/lib/python3.7/site-packages/requests/sessions.py", line 645, in send
    r = adapter.send(request, **kwargs)
  File "/home/scau/anaconda3/envs/yolov5/lib/python3.7/site-packages/requests/adapters.py", line 507, in send
    raise ConnectTimeout(e, request=request)
requests.exceptions.ConnectTimeout: HTTPSConnectionPool(host='api.wandb.ai', port=443): Max retries exceeded with url: /graphql (Caused by ConnectTimeoutError(<urllib3.connection.HTTPSConnection object at 0x7fa8944df240>, 'Connection to api.wandb.ai timed out. (connect timeout=10)'))
