2022-06-23 16:01:23,559 INFO    MainThread:7604 [internal.py:wandb_internal():93] W&B internal server running at pid: 7604, started at: 2022-06-23 16:01:23.559085
2022-06-23 16:01:23,560 INFO    WriterThread:7604 [datastore.py:open_for_write():75] open: /media/scau/21B1CA0D9A1CBC09/DL/yolov5_obb-master/yolov5_obb-master/wandb/run-20220623_160123-orei4fgt/run-orei4fgt.wandb
2022-06-23 16:01:23,562 DEBUG   SenderThread:7604 [sender.py:send():235] send: header
2022-06-23 16:01:23,562 DEBUG   SenderThread:7604 [sender.py:send():235] send: run
2022-06-23 16:01:23,569 INFO    SenderThread:7604 [sender.py:_maybe_setup_resume():493] checking resume status for None/YOLOv5/orei4fgt
2022-06-23 16:01:53,182 DEBUG   HandlerThread:7604 [handler.py:handle_request():141] handle_request: shutdown
2022-06-23 16:01:53,184 INFO    HandlerThread:7604 [handler.py:finish():806] shutting down handler
2022-06-23 16:01:53,567 INFO    WriterThread:7604 [datastore.py:close():279] close: /media/scau/21B1CA0D9A1CBC09/DL/yolov5_obb-master/yolov5_obb-master/wandb/run-20220623_160123-orei4fgt/run-orei4fgt.wandb
2022-06-23 16:02:32,070 ERROR   SenderThread:7604 [retry.py:__call__():126] Retry attempt failed:
Traceback (most recent call last):
  File "/home/scau/anaconda3/envs/yolov5/lib/python3.7/site-packages/urllib3/connection.py", line 175, in _new_conn
    (self._dns_host, self.port), self.timeout, **extra_kw
  File "/home/scau/anaconda3/envs/yolov5/lib/python3.7/site-packages/urllib3/util/connection.py", line 72, in create_connection
    for res in socket.getaddrinfo(host, port, family, socket.SOCK_STREAM):
  File "/home/scau/anaconda3/envs/yolov5/lib/python3.7/socket.py", line 748, in getaddrinfo
    for res in _socket.getaddrinfo(host, port, family, type, proto, flags):
socket.gaierror: [Errno -2] Name or service not known

During handling of the above exception, another exception occurred:

Traceback (most recent call last):
  File "/home/scau/anaconda3/envs/yolov5/lib/python3.7/site-packages/urllib3/connectionpool.py", line 710, in urlopen
    chunked=chunked,
  File "/home/scau/anaconda3/envs/yolov5/lib/python3.7/site-packages/urllib3/connectionpool.py", line 386, in _make_request
    self._validate_conn(conn)
  File "/home/scau/anaconda3/envs/yolov5/lib/python3.7/site-packages/urllib3/connectionpool.py", line 1040, in _validate_conn
    conn.connect()
  File "/home/scau/anaconda3/envs/yolov5/lib/python3.7/site-packages/urllib3/connection.py", line 358, in connect
    self.sock = conn = self._new_conn()
  File "/home/scau/anaconda3/envs/yolov5/lib/python3.7/site-packages/urllib3/connection.py", line 187, in _new_conn
    self, "Failed to establish a new connection: %s" % e
urllib3.exceptions.NewConnectionError: <urllib3.connection.HTTPSConnection object at 0x7fd35ed90898>: Failed to establish a new connection: [Errno -2] Name or service not known

During handling of the above exception, another exception occurred:

Traceback (most recent call last):
  File "/home/scau/anaconda3/envs/yolov5/lib/python3.7/site-packages/requests/adapters.py", line 450, in send
    timeout=timeout
  File "/home/scau/anaconda3/envs/yolov5/lib/python3.7/site-packages/urllib3/connectionpool.py", line 786, in urlopen
    method, url, error=e, _pool=self, _stacktrace=sys.exc_info()[2]
  File "/home/scau/anaconda3/envs/yolov5/lib/python3.7/site-packages/urllib3/util/retry.py", line 592, in increment
    raise MaxRetryError(_pool, url, error or ResponseError(cause))
urllib3.exceptions.MaxRetryError: HTTPSConnectionPool(host='api.wandb.ai', port=443): Max retries exceeded with url: /graphql (Caused by NewConnectionError('<urllib3.connection.HTTPSConnection object at 0x7fd35ed90898>: Failed to establish a new connection: [Errno -2] Name or service not known'))

During handling of the above exception, another exception occurred:

Traceback (most recent call last):
  File "/home/scau/anaconda3/envs/yolov5/lib/python3.7/site-packages/wandb/sdk/lib/retry.py", line 102, in __call__
    result = self._call_fn(*args, **kwargs)
  File "/home/scau/anaconda3/envs/yolov5/lib/python3.7/site-packages/wandb/sdk/internal/internal_api.py", line 140, in execute
    return self.client.execute(*args, **kwargs)
  File "/home/scau/anaconda3/envs/yolov5/lib/python3.7/site-packages/wandb/vendor/gql-0.2.0/wandb_gql/client.py", line 52, in execute
    result = self._get_result(document, *args, **kwargs)
  File "/home/scau/anaconda3/envs/yolov5/lib/python3.7/site-packages/wandb/vendor/gql-0.2.0/wandb_gql/client.py", line 60, in _get_result
    return self.transport.execute(document, *args, **kwargs)
  File "/home/scau/anaconda3/envs/yolov5/lib/python3.7/site-packages/wandb/vendor/gql-0.2.0/wandb_gql/transport/requests.py", line 38, in execute
    request = requests.post(self.url, **post_args)
  File "/home/scau/anaconda3/envs/yolov5/lib/python3.7/site-packages/requests/api.py", line 117, in post
    return request('post', url, data=data, json=json, **kwargs)
  File "/home/scau/anaconda3/envs/yolov5/lib/python3.7/site-packages/requests/api.py", line 61, in request
    return session.request(method=method, url=url, **kwargs)
  File "/home/scau/anaconda3/envs/yolov5/lib/python3.7/site-packages/requests/sessions.py", line 529, in request
    resp = self.send(prep, **send_kwargs)
  File "/home/scau/anaconda3/envs/yolov5/lib/python3.7/site-packages/requests/sessions.py", line 645, in send
    r = adapter.send(request, **kwargs)
  File "/home/scau/anaconda3/envs/yolov5/lib/python3.7/site-packages/requests/adapters.py", line 519, in send
    raise ConnectionError(e, request=request)
requests.exceptions.ConnectionError: HTTPSConnectionPool(host='api.wandb.ai', port=443): Max retries exceeded with url: /graphql (Caused by NewConnectionError('<urllib3.connection.HTTPSConnection object at 0x7fd35ed90898>: Failed to establish a new connection: [Errno -2] Name or service not known'))
